#### python单元测试

### 测试工具

#### 1.1：unittest： 通用的测试框架

优点：可以以结构化的方式编写大型且周详的测试集，使用的是unittest模块的TestCase类



被测试文件：

mymath.py
```
def product(x,y):
    return x*y
```

建立测试文件  

test_mymath.py
```
import unittest,mymath

class ProductTestCase(unittest.TestCase):
    def testIntergers(self):
        for x in xrange(-10,10):
            for y in xrange(-10,10):
                p = mymath.product(x,y)
                self.failUnless(p == x*y, 'Integer multiplication failed')

    def testFloats(self):
        for x in xrange(-10,10):
            for y in xrange(-10,10):
                x = x/10.0
                y = y/10.0
                p = mymath.product(x,y)
            self.failUnless(p == x*y, 'Float multiplication failed')
    def setUp(self):
        print "Start the test"
    def tearDown(self):
        print "End the test"

if __name__=='__main__':unittest.main()

```

更多TestCase方法需要进行查询，比如aasert_、failUnless、failIfEqual等等

unittest.main函数负责实际运行所有测试，实例化所有TestCase的子类，运行所有名字以test开头的方法  setUp和tearDown函数实在每个测试方法之前和之后进行执行




















#### 1.2:doctest: 比较简单，检查文档用

test.py
```
def square(x):
    '''
    Square a number and returns the result
    
    >>> square(2)
    4
    >>> square(3)
    9
    '''
    return x*x

if __name__=='__main__':
    import doctest, test
    doctest.testmod(test)
```

这样直接运行 >python test.py 
的话，不会报错，或者运行>python test.py -v获得更详细的信息

但是将return x*x改成2*x就会报错

```
C:\Users\yuzhipeng\Desktop>python test.py
**********************************************************************
File "C:\Users\yuzhipeng\Desktop\test.py", line 7, in test.square
Failed example:
    square(3)
Expected:
    9
Got:
    6
**********************************************************************
1 items had failures:
   1 of   2 in test.square
***Test Failed*** 1 failures.
```

今天犯了一个比较恶心的错误，我建立了一个文件命名math，在引入的时候各种问题，后来突然恍然大悟，math是个标准模块，所以自己写的那些东西显示不出来。